Cannot initiate the connection to us.archive.ubuntu.com:80 (2001:67c:1562::18). - connect (101: Network is unreachable) Cannot initiate the connection to us.archive.ubuntu.com:80 (2001:67c:1562::15). - connect (101: Network is unreachable)
Err:11 http://us.archive.ubuntu.com/ubuntu jammy-backports InRelease                                                
  Cannot initiate the connection to us.archive.ubuntu.com:80 (2001:67c:1562::18). - connect (101: Network is unreachable) Cannot initiate the connection to us.archive.ubuntu.com:80 (2001:67c:1562::15). - connect (101: Network is unreachable)
Get:12 http://security.ubuntu.com/ubuntu jammy-security/main Translation-en [129 kB]                                
Get:13 http://security.ubuntu.com/ubuntu jammy-security/main amd64 DEP-11 Metadata [41.6 kB]                        
Get:14 http://security.ubuntu.com/ubuntu jammy-security/main DEP-11 48x48 Icons [13.8 kB]                           
Get:15 http://security.ubuntu.com/ubuntu jammy-security/main DEP-11 64x64 Icons [22.7 kB]                           
Get:16 http://security.ubuntu.com/ubuntu jammy-security/main amd64 c-n-f Metadata [10.3 kB]                         
Get:17 http://security.ubuntu.com/ubuntu jammy-security/restricted i386 Packages [28.0 kB]                          
Get:18 http://security.ubuntu.com/ubuntu jammy-security/restricted amd64 Packages [415 kB]                          
Get:19 http://security.ubuntu.com/ubuntu jammy-security/restricted Translation-en [63.3 kB]                         
Get:20 http://security.ubuntu.com/ubuntu jammy-security/restricted amd64 c-n-f Metadata [604 B]                     
Get:21 http://security.ubuntu.com/ubuntu jammy-security/universe amd64 Packages [737 kB]                            
Get:22 http://security.ubuntu.com/ubuntu jammy-security/universe i386 Packages [535 kB]                             
Get:23 http://security.ubuntu.com/ubuntu jammy-security/universe Translation-en [130 kB]                            
Get:24 http://security.ubuntu.com/ubuntu jammy-security/universe amd64 DEP-11 Metadata [22.0 kB]                    
Get:25 http://security.ubuntu.com/ubuntu jammy-security/universe DEP-11 48x48 Icons [19.7 kB]                       
Get:26 http://security.ubuntu.com/ubuntu jammy-security/universe DEP-11 64x64 Icons [31.7 kB]                       
Get:27 http://security.ubuntu.com/ubuntu jammy-security/universe amd64 c-n-f Metadata [15.6 kB]                     
Get:28 http://security.ubuntu.com/ubuntu jammy-security/multiverse amd64 Packages [30.2 kB]                         
Get:29 http://security.ubuntu.com/ubuntu jammy-security/multiverse Translation-en [5,828 B]                         
Get:30 http://security.ubuntu.com/ubuntu jammy-security/multiverse amd64 c-n-f Metadata [252 B]                     
Reading package lists... Done                                                                                       
W: GPG error: https://download.docker.com/linux/ubuntu jammy InRelease: The following signatures couldn't be verified because the public key is not available: NO_PUBKEY 7EA0A9C3F273FCD8
E: The repository 'https://download.docker.com/linux/ubuntu jammy InRelease' is not signed.
N: Updating from such a repository can't be done securely, and is therefore disabled by default.
N: See apt-secure(8) manpage for repository creation and user configuration details.
osboxes@osboxes:~/Documents/projets/censor-management/src/frontend/dash-plotly$ sudo apt update
Hit:1 http://packages.microsoft.com/repos/code stable InRelease                                 
Get:2 https://download.docker.com/linux/ubuntu jammy InRelease [48.9 kB]                                             
Hit:3 http://security.ubuntu.com/ubuntu jammy-security InRelease                                                     
Err:2 https://download.docker.com/linux/ubuntu jammy InRelease                  
  The following signatures couldn't be verified because the public key is not available: NO_PUBKEY 7EA0A9C3F273FCD8
Hit:4 http://us.archive.ubuntu.com/ubuntu jammy InRelease
Get:5 http://us.archive.ubuntu.com/ubuntu jammy-updates InRelease [119 kB]
Ign:5 http://us.archive.ubuntu.com/ubuntu jammy-updates InRelease                                                    
Ign:6 http://us.archive.ubuntu.com/ubuntu jammy-backports InRelease                                                  
0% [Waiting for headers]^C                           
osboxes@osboxes:~/Documents/projets/censor-management/src/frontend/dash-plotly$ pip --version
Command 'pip' not found, but can be installed with:
sudo apt install python3-pip
osboxes@osboxes:~/Documents/projets/censor-management/src/frontend/dash-plotly$ sudo apt install python3-pip
Waiting for cache lock: Could not get lock /var/lib/dpkg/lock-frontend. It is held by process 6652 (unattended-upgr)..Waiting for cache lock: Could not get lock /var/lib/dpkg/lock-frontend. It is held by process 6652 (unattended-upgr)      
Waiting for cache lock: Could not get lock /var/lib/dpkg/lock-frontend. It is held by process 6652 (unattended-upgr)..Waiting for cache lock: Could not get lock /var/lib/dpkg/lock-frontend. It is held by process 6652 (unattended-upgr)      
Waiting for cache lock: Could not get lock /var/lib/dpkg/lock-frontend. It is held by process 6652 (unattended-upgr)..Waiting for cache lock: Could not get lock /var/lib/dpkg/lock-frontend. It is held by process 6652 (unattended-upgr)      
Waiting for cache lock: Could not get lock /var/lib/dpkg/lock-frontend. It is held by process 6652 (unattended-upgr)..Waiting for cache lock: Could not get lock /var/lib/dpkg/lock-frontend. It is held by process 6652 (unattended-upgr)      
Waiting for cache lock: Could not get lock /var/lib/dpkg/lock-frontend. It is held by process 6652 (unattended-upgr)..Waiting for cache lock: Could not get lock /var/lib/dpkg/lock-frontend. It is held by process 6652 (unattended-upgr)      
Waiting for cache lock: Could not get lock /var/lib/dpkg/lock-frontend. It is held by process 6652 (unattended-upgr)..Waiting for cache lock: Could not get lock /var/lib/dpkg/lock-frontend. It is held by process 6652 (unattended-upgr)      
Waiting for cache lock: Could not get lock /var/lib/dpkg/lock-frontend. It is held by process 6652 (unattended-upgr)..Waiting for cache lock: Could not get lock /var/lib/dpkg/lock-frontend. It is held by process 6652 (unattended-upgr)      
Waiting for cache lock: Could not get lock /var/lib/dpkg/lock-frontend. It is held by process 6652 (unattended-upgr)..Waiting for cache lock: Could not get lock /var/lib/dpkg/lock-frontend. It is held by process 6652 (unattended-upgr)      
Waiting for cache lock: Could not get lock /var/lib/dpkg/lock-frontend. It is held by process 6652 (unattended-upgr)..Waiting for cache lock: Could not get lock /var/lib/dpkg/lock-frontend. It is held by process 6652 (unattended-upgr)      
Waiting for cache lock: Could not get lock /var/lib/dpkg/lock-frontend. It is held by process 6652 (unattended-upgr)..Waiting for cache lock: Could not get lock /var/lib/dpkg/lock-frontend. It is held by process 6652 (unattended-upgr)      
Waiting for cache lock: Could not get lock /var/lib/dpkg/lock-frontend. It is held by process 6652 (unattended-upgr)..^C10s
osboxes@osboxes:~/Documents/projets/censor-management/src/frontend/dash-plotly$ kill 6652
bash: kill: (6652) - Operation not permitted
osboxes@osboxes:~/Documents/projets/censor-management/src/frontend/dash-plotly$ sudo kill 6652
osboxes@osboxes:~/Documents/projets/censor-management/src/frontend/dash-plotly$ sudo apt install python3-pip
Waiting for cache lock: Could not get lock /var/lib/dpkg/lock-frontend. It is held by process 6652 (unattended-upgr)..Waiting for cache lock: Could not get lock /var/lib/dpkg/lock-frontend. It is held by process 6652 (unattended-upgr)      
Waiting for cache lock: Could not get lock /var/lib/dpkg/lock-frontend. It is held by process 6652 (unattended-upgr)..Waiting for cache lock: Could not get lock /var/lib/dpkg/lock-frontend. It is held by process 6652 (unattended-upgr)      
Waiting for cache lock: Could not get lock /var/lib/dpkg/lock-frontend. It is held by process 6652 (unattended-upgr)..Waiting for cache lock: Could not get lock /var/lib/dpkg/lock-frontend. It is held by process 6652 (unattended-upgr)      
Waiting for cache lock: Could not get lock /var/lib/dpkg/lock-frontend. It is held by process 6652 (unattended-upgr)..Waiting for cache lock: Could not get lock /var/lib/dpkg/lock-frontend. It is held by process 6652 (unattended-upgr)      
Waiting for cache lock: Could not get lock /var/lib/dpkg/lock-frontend. It is held by process 6652 (unattended-upgr)..Waiting for cache lock: Could not get lock /var/lib/dpkg/lock-frontend. It is held by process 6652 (unattended-upgr)      
Waiting for cache lock: Could not get lock /var/lib/dpkg/lock-frontend. It is held by process 6652 (unattended-upgr)..Waiting for cache lock: Could not get lock /var/lib/dpkg/lock-frontend. It is held by process 6652 (unattended-upgr)      
Waiting for cache lock: Could not get lock /var/lib/dpkg/lock-frontend. It is held by process 6652 (unattended-upgr)..Waiting for cache lock: Could not get lock /var/lib/dpkg/lock-frontend. It is held by process 6652 (unattended-upgr)      
Waiting for cache lock: Could not get lock /var/lib/dpkg/lock-frontend. It is held by process 6652 (unattended-upgr)... 7s
 *  History restored 

osboxes@osboxes:~/Documents/projets/censor-management/src/frontend/dash-plotly$ pip --version
pip 22.0.2 from /usr/lib/python3/dist-packages/pip (python 3.10)
osboxes@osboxes:~/Documents/projets/censor-management/src/frontend/dash-plotly$ ls
Dockerfile  requirements.txt  src
osboxes@osboxes:~/Documents/projets/censor-management/src/frontend/dash-plotly$ pip install -r requirements.txt 
Defaulting to user installation because normal site-packages is not writeable
WARNING: Retrying (Retry(total=4, connect=None, read=None, redirect=None, status=None)) after connection broken by 'NewConnectionError('<pip._vendor.urllib3.connection.HTTPSConnection object at 0x7f0775aa74c0>: Failed to establish a new connection: [Errno -3] Temporary failure in name resolution')': /simple/dash/
WARNING: Retrying (Retry(total=3, connect=None, read=None, redirect=None, status=None)) after connection broken by 'NewConnectionError('<pip._vendor.urllib3.connection.HTTPSConnection object at 0x7f0775aa76d0>: Failed to establish a new connection: [Errno -3] Temporary failure in name resolution')': /simple/dash/
WARNING: Retrying (Retry(total=2, connect=None, read=None, redirect=None, status=None)) after connection broken by 'NewConnectionError('<pip._vendor.urllib3.connection.HTTPSConnection object at 0x7f0775aa78e0>: Failed to establish a new connection: [Errno -3] Temporary failure in name resolution')': /simple/dash/
WARNING: Retrying (Retry(total=1, connect=None, read=None, redirect=None, status=None)) after connection broken by 'NewConnectionError('<pip._vendor.urllib3.connection.HTTPSConnection object at 0x7f0775aa7a90>: Failed to establish a new connection: [Errno -3] Temporary failure in name resolution')': /simple/dash/
WARNING: Retrying (Retry(total=0, connect=None, read=None, redirect=None, status=None)) after connection broken by 'NewConnectionError('<pip._vendor.urllib3.connection.HTTPSConnection object at 0x7f0775aa7c40>: Failed to establish a new connection: [Errno -3] Temporary failure in name resolution')': /simple/dash/
ERROR: Could not find a version that satisfies the requirement dash (from versions: none)
ERROR: No matching distribution found for dash
osboxes@osboxes:~/Documents/projets/censor-management/src/frontend/dash-plotly$ pip install -r requirements.txt 
Defaulting to user installation because normal site-packages is not writeable
Collecting dash
  Downloading dash-2.10.2-py3-none-any.whl (10.3 MB)
     ━━━━━━━━━━━━━━━━━━━━━━━━━━━━━━━━━━━━━━━━ 0.1/10.3 MB 166.8 kB/s eta 0:01:02
ERROR: Exception:
Traceback (most recent call last):
  File "/usr/lib/python3/dist-packages/pip/_vendor/urllib3/response.py", line 438, in _error_catcher
    yield
  File "/usr/lib/python3/dist-packages/pip/_vendor/urllib3/response.py", line 519, in read
    data = self._fp.read(amt) if not fp_closed else b""
  File "/usr/lib/python3/dist-packages/pip/_vendor/cachecontrol/filewrapper.py", line 90, in read
    data = self.__fp.read(amt)
  File "/usr/lib/python3.10/http/client.py", line 465, in read
    s = self.fp.read(amt)
  File "/usr/lib/python3.10/socket.py", line 705, in readinto
    return self._sock.recv_into(b)
  File "/usr/lib/python3.10/ssl.py", line 1274, in recv_into
    return self.read(nbytes, buffer)
  File "/usr/lib/python3.10/ssl.py", line 1130, in read
    return self._sslobj.read(len, buffer)
TimeoutError: The read operation timed out

During handling of the above exception, another exception occurred:

Traceback (most recent call last):
  File "/usr/lib/python3/dist-packages/pip/_internal/cli/base_command.py", line 165, in exc_logging_wrapper
    status = run_func(*args)
  File "/usr/lib/python3/dist-packages/pip/_internal/cli/req_command.py", line 205, in wrapper
    return func(self, options, args)
  File "/usr/lib/python3/dist-packages/pip/_internal/commands/install.py", line 339, in run
    requirement_set = resolver.resolve(
  File "/usr/lib/python3/dist-packages/pip/_internal/resolution/resolvelib/resolver.py", line 94, in resolve
    result = self._result = resolver.resolve(
  File "/usr/lib/python3/dist-packages/pip/_vendor/resolvelib/resolvers.py", line 481, in resolve
    state = resolution.resolve(requirements, max_rounds=max_rounds)
  File "/usr/lib/python3/dist-packages/pip/_vendor/resolvelib/resolvers.py", line 348, in resolve
    self._add_to_criteria(self.state.criteria, r, parent=None)
  File "/usr/lib/python3/dist-packages/pip/_vendor/resolvelib/resolvers.py", line 172, in _add_to_criteria
    if not criterion.candidates:
  File "/usr/lib/python3/dist-packages/pip/_vendor/resolvelib/structs.py", line 151, in __bool__
    return bool(self._sequence)
  File "/usr/lib/python3/dist-packages/pip/_internal/resolution/resolvelib/found_candidates.py", line 155, in __bool__
    return any(self)
  File "/usr/lib/python3/dist-packages/pip/_internal/resolution/resolvelib/found_candidates.py", line 143, in <genexpr>
    return (c for c in iterator if id(c) not in self._incompatible_ids)
  File "/usr/lib/python3/dist-packages/pip/_internal/resolution/resolvelib/found_candidates.py", line 47, in _iter_built
    candidate = func()
  File "/usr/lib/python3/dist-packages/pip/_internal/resolution/resolvelib/factory.py", line 215, in _make_candidate_from_link
    self._link_candidate_cache[link] = LinkCandidate(
  File "/usr/lib/python3/dist-packages/pip/_internal/resolution/resolvelib/candidates.py", line 288, in __init__
    super().__init__(
  File "/usr/lib/python3/dist-packages/pip/_internal/resolution/resolvelib/candidates.py", line 158, in __init__
    self.dist = self._prepare()
  File "/usr/lib/python3/dist-packages/pip/_internal/resolution/resolvelib/candidates.py", line 227, in _prepare
    dist = self._prepare_distribution()
  File "/usr/lib/python3/dist-packages/pip/_internal/resolution/resolvelib/candidates.py", line 299, in _prepare_distribution
    return preparer.prepare_linked_requirement(self._ireq, parallel_builds=True)
  File "/usr/lib/python3/dist-packages/pip/_internal/operations/prepare.py", line 487, in prepare_linked_requirement
    return self._prepare_linked_requirement(req, parallel_builds)
  File "/usr/lib/python3/dist-packages/pip/_internal/operations/prepare.py", line 532, in _prepare_linked_requirement
    local_file = unpack_url(
  File "/usr/lib/python3/dist-packages/pip/_internal/operations/prepare.py", line 214, in unpack_url
    file = get_http_url(
  File "/usr/lib/python3/dist-packages/pip/_internal/operations/prepare.py", line 94, in get_http_url
    from_path, content_type = download(link, temp_dir.path)
  File "/usr/lib/python3/dist-packages/pip/_internal/network/download.py", line 146, in __call__
    for chunk in chunks:
  File "/usr/lib/python3/dist-packages/pip/_internal/cli/progress_bars.py", line 304, in _rich_progress_bar
    for chunk in iterable:
  File "/usr/lib/python3/dist-packages/pip/_internal/network/utils.py", line 63, in response_chunks
    for chunk in response.raw.stream(
  File "/usr/lib/python3/dist-packages/pip/_vendor/urllib3/response.py", line 576, in stream
    data = self.read(amt=amt, decode_content=decode_content)
  File "/usr/lib/python3/dist-packages/pip/_vendor/urllib3/response.py", line 512, in read
    with self._error_catcher():
  File "/usr/lib/python3.10/contextlib.py", line 153, in __exit__
    self.gen.throw(typ, value, traceback)
  File "/usr/lib/python3/dist-packages/pip/_vendor/urllib3/response.py", line 443, in _error_catcher
    raise ReadTimeoutError(self._pool, None, "Read timed out.")
pip._vendor.urllib3.exceptions.ReadTimeoutError: HTTPSConnectionPool(host='files.pythonhosted.org', port=443): Read timed out.
osboxes@osboxes:~/Documents/projets/censor-management/src/frontend/dash-plotly$ pip install -r requirements.txt 
Defaulting to user installation because normal site-packages is not writeable
WARNING: Retrying (Retry(total=4, connect=None, read=None, redirect=None, status=None)) after connection broken by 'NewConnectionError('<pip._vendor.urllib3.connection.HTTPSConnection object at 0x7fcd69f9b400>: Failed to establish a new connection: [Errno -3] Temporary failure in name resolution')': /simple/dash/
Collecting dash
  Downloading dash-2.10.2-py3-none-any.whl (10.3 MB)
     ━━━━━━━━━━━━━━━━━━━━━━━━━━━━━━━━━━━━━━━━ 10.3/10.3 MB 82.8 kB/s eta 0:00:00
WARNING: Retrying (Retry(total=4, connect=None, read=None, redirect=None, status=None)) after connection broken by 'ReadTimeoutError("HTTPSConnectionPool(host='pypi.org', port=443): Read timed out. (read timeout=15)")': /simple/dash-daq/
WARNING: Retrying (Retry(total=3, connect=None, read=None, redirect=None, status=None)) after connection broken by 'ReadTimeoutError("HTTPSConnectionPool(host='pypi.org', port=443): Read timed out. (read timeout=15)")': /simple/dash-daq/
Collecting dash_daq
  WARNING: Retrying (Retry(total=4, connect=None, read=None, redirect=None, status=None)) after connection broken by 'ReadTimeoutError("HTTPSConnectionPool(host='files.pythonhosted.org', port=443): Read timed out. (read timeout=15)")': /packages/16/c1/9c6adfc3646990965a5b2ca073f579cc9c09d15553fcfcd83aefd1255494/dash_daq-0.5.0.tar.gz
  Downloading dash_daq-0.5.0.tar.gz (642 kB)
     ━━━━━━━━━━━━━━━━━━━━━━━━━━━━━━━━━━━━━━━━ 642.7/642.7 KB 163.5 kB/s eta 0:00:00
  Preparing metadata (setup.py) ... done
Collecting plotly
  Downloading plotly-5.15.0-py2.py3-none-any.whl (15.5 MB)
     ━━━━━━━━━━━━━━━━━━━━━━━━━━━━━━━━━━━━━━━━ 15.5/15.5 MB 92.6 kB/s eta 0:00:00
Collecting pandas
  Downloading pandas-2.0.2-cp310-cp310-manylinux_2_17_x86_64.manylinux2014_x86_64.whl (12.3 MB)
     ━━━━━━━━━━━━━━━━━━━━━━━━━━━━━━━━━━━━━━━━ 12.3/12.3 MB 93.7 kB/s eta 0:00:00
Collecting gunicorn
  Downloading gunicorn-20.1.0-py3-none-any.whl (79 kB)
     ━━━━━━━━━━━━━━━━━━━━━━━━━━━━━━━━━━━━━━━━ 79.5/79.5 KB 74.0 kB/s eta 0:00:00
Requirement already satisfied: requests in /usr/lib/python3/dist-packages (from -r requirements.txt (line 8)) (2.25.1)
Collecting dash-core-components==2.0.0
  Downloading dash_core_components-2.0.0-py3-none-any.whl (3.8 kB)
Collecting dash-html-components==2.0.0
  Downloading dash_html_components-2.0.0-py3-none-any.whl (4.1 kB)
Collecting dash-table==5.0.0
  Downloading dash_table-5.0.0-py3-none-any.whl (3.9 kB)
Collecting Werkzeug<2.3.0
  Downloading Werkzeug-2.2.3-py3-none-any.whl (233 kB)
     ━━━━━━━━━━━━━━━━━━━━━━━━━━━━━━━━━━━━━━━━ 233.6/233.6 KB 79.2 kB/s eta 0:00:00
Collecting Flask<2.3.0,>=1.0.4
  Downloading Flask-2.2.5-py3-none-any.whl (101 kB)
     ━━━━━━━━━━━━━━━━━━━━━━━━━━━━━━━━━━━━━━━━ 101.8/101.8 KB 102.2 kB/s eta 0:00:00
Collecting packaging
  Downloading packaging-23.1-py3-none-any.whl (48 kB)
     ━━━━━━━━━━━━━━━━━━━━━━━━━━━━━━━━━━━━━━━━ 48.9/48.9 KB 89.1 kB/s eta 0:00:00
Collecting tenacity>=6.2.0
  Downloading tenacity-8.2.2-py3-none-any.whl (24 kB)
Requirement already satisfied: pytz>=2020.1 in /usr/lib/python3/dist-packages (from pandas->-r requirements.txt (line 4)) (2022.1)
Collecting tzdata>=2022.1
  Downloading tzdata-2023.3-py2.py3-none-any.whl (341 kB)
     ━━━━━━━━━━━━━━━━━━━━━━━━━━━━━━━━━━━━━━━━ 341.8/341.8 KB 65.4 kB/s eta 0:00:00
Collecting numpy>=1.21.0
  Downloading numpy-1.25.0-cp310-cp310-manylinux_2_17_x86_64.manylinux2014_x86_64.whl (17.6 MB)
     ━━━━━━━━━━━━━━━━━━━━━━━━━━━━━━━━━━━━━━━━ 17.6/17.6 MB 120.2 kB/s eta 0:00:00
Collecting python-dateutil>=2.8.2
  Downloading python_dateutil-2.8.2-py2.py3-none-any.whl (247 kB)
     ━━━━━━━━━━━━━━━━━━━━━━━━━━━━━━━━━━━━━━━━ 247.7/247.7 KB 114.4 kB/s eta 0:00:00
Requirement already satisfied: setuptools>=3.0 in /usr/lib/python3/dist-packages (from gunicorn->-r requirements.txt (line 5)) (59.6.0)
Collecting itsdangerous>=2.0
  Downloading itsdangerous-2.1.2-py3-none-any.whl (15 kB)
Requirement already satisfied: click>=8.0 in /usr/lib/python3/dist-packages (from Flask<2.3.0,>=1.0.4->dash->-r requirements.txt (line 1)) (8.0.3)
Collecting Jinja2>=3.0
  Downloading Jinja2-3.1.2-py3-none-any.whl (133 kB)
     ━━━━━━━━━━━━━━━━━━━━━━━━━━━━━━━━━━━━━━━━ 133.1/133.1 KB 235.0 kB/s eta 0:00:00
Requirement already satisfied: six>=1.5 in /usr/lib/python3/dist-packages (from python-dateutil>=2.8.2->pandas->-r requirements.txt (line 4)) (1.16.0)
Collecting MarkupSafe>=2.1.1
  Downloading MarkupSafe-2.1.3-cp310-cp310-manylinux_2_17_x86_64.manylinux2014_x86_64.whl (25 kB)
Building wheels for collected packages: dash_daq
  Building wheel for dash_daq (setup.py) ... done
  Created wheel for dash_daq: filename=dash_daq-0.5.0-py3-none-any.whl size=669714 sha256=01ebc0142228baa93a66305e42d76dcab69d45e88c2195bf0f89e91275f622e8
  Stored in directory: /home/osboxes/.cache/pip/wheels/75/14/1b/208d09d5e239391048bdc167759977b41ba65a3d4063aebf6b
Successfully built dash_daq
Installing collected packages: dash-table, dash-html-components, dash-core-components, tzdata, tenacity, python-dateutil, packaging, numpy, MarkupSafe, itsdangerous, gunicorn, Werkzeug, plotly, pandas, Jinja2, Flask, dash, dash_daq
  WARNING: The scripts f2py, f2py3 and f2py3.10 are installed in '/home/osboxes/.local/bin' which is not on PATH.
  Consider adding this directory to PATH or, if you prefer to suppress this warning, use --no-warn-script-location.
  WARNING: The script gunicorn is installed in '/home/osboxes/.local/bin' which is not on PATH.
  Consider adding this directory to PATH or, if you prefer to suppress this warning, use --no-warn-script-location.
  WARNING: The script flask is installed in '/home/osboxes/.local/bin' which is not on PATH.
  Consider adding this directory to PATH or, if you prefer to suppress this warning, use --no-warn-script-location.
  WARNING: The scripts dash-generate-components, dash-update-components and renderer are installed in '/home/osboxes/.local/bin' which is not on PATH.
  Consider adding this directory to PATH or, if you prefer to suppress this warning, use --no-warn-script-location.
Successfully installed Flask-2.2.5 Jinja2-3.1.2 MarkupSafe-2.1.3 Werkzeug-2.2.3 dash-2.10.2 dash-core-components-2.0.0 dash-html-components-2.0.0 dash-table-5.0.0 dash_daq-0.5.0 gunicorn-20.1.0 itsdangerous-2.1.2 numpy-1.25.0 packaging-23.1 pandas-2.0.2 plotly-5.15.0 python-dateutil-2.8.2 tenacity-8.2.2 tzdata-2023.3
osboxes@osboxes:~/Documents/projets/censor-management/src/frontend/dash-plotly$ 